File: fatigue/fatigue_data.csv
SL.No,No of cycles,fatigue stress(strength) (MPa),Solution temp (cel),Sol time (hrs),Temp.  measurement  (cel),Ann/Age. temp (cel),Ann/age time (hrs),total strain (%),R,Frequency(Hz),Ti,Al,V,C,N,O,H,Fe,Si,Sn,Nb,Mo,Zr
1,86,1067.63,1020,1,25,700,2,1.25,-1,0.2,84.9,5.8,0,0.05,0.0025,0,0.004,0,0.34,4,0.7,0.5,3.7
2,102,685.38,1025,2,450,1025,2,1,0,0,85.01,5.75,0,0.065,0.002,0.09,0,0,0.305,4.02,0.71,0.505,3.54
3,103,725,1025,2,375,1025,2,1,0,0,85.01,5.75,0,0.065,0.002,0.09,0,0,0.305,4.02,0.71,0.505,3.54
4,103,700.06,1025,2,400,1025,2,1,0,0,85.01,5.75,0,0.065,0.002,0.09,0,0,0.305,4.02,0.71,0.505,3.54
5,103,711.56,1025,2,425,1025,2,1,0,0,85.01,5.75,0,0.065,0.002,0.09,0,0,0.305,4.02,0.71,0.505,3.54
6,103,649.41,1025,2,500,1025,2,1,0,0,85.01,5.75,0,0.065,0.002,0.09,0,0,0.305,4.02,0.71,0.505,3.54
7,116,912.52,1020,1,25,0,0,0.8,-1,0.2,84.9,5.8,0,0.05,0.0025,0,0.004,0,0.34,4,0.7,0.5,3.7
8,143,1061.22,1020,1,25,700,2,1.25,-1,0.2,84.9,5.8,0,0.05,0.0025,0,0.004,0,0.34,4,0.7,0.5,3.7
9,148,910.33,1020,1,25,0,0,0.8,-1,0.2,84.9,5.8,0,0.05,0.0025,0,0.004,0,0.34,4,0.7,0.5,3.7
10,149,928.1,1020,1,25,700,2,1,-1,0.2,84.9,5.8,0,0.05,0.0025,0,0.004,0,0.34,4,0.7,0.5,3.7
11,173,935.34,1020,1,25,700,2,1,-1,0.2,84.9,5.8,0,0.05,0.0025,0,0.004,0,0.34,4,0.7,0.5,3.7
12,182,1059.34,1020,1,25,700,2,1.25,-1,0.2,84.9,5.8,0,0.05,0.0025,0,0.004,0,0.34,4,0.7,0.5,3.7
13,209,918.5,1020,1,25,0,0,0.8,-1,0.2,84.9,5.8,0,0.05,0.0025,0,0.004,0,0.34,4,0.7,0.5,3.7
14,211,935.22,1020,1,25,700,2,1,-1,0.2,84.9,5.8,0,0.05,0.0025,0,0.004,0,0.34,4,0.7,0.5,3.7
15,234,695.05,1025,2,450,1025,2,1,0,0,85.01,5.75,0,0.065,0.002,0.09,0,0,0.305,4.02,0.71,0.505,3.54
16,235,1049.37,1025,2,25,700,2,1.25,-1,0.2,84.9,5.8,0,0.05,0.0025,0,0.004,0,0.34,4,0.7,0.5,3.7
17,235,709.43,1020,1,425,1025,2,1,0,0,85.01,5.75,0,0.065,0.002,0.09,0,0,0.305,4.02,0.71,0.505,3.54
18,249,915.24,1020,1,25,0,0,0.8,-1,0.2,84.9,5.8,0,0.05,0.0025,0,0.004,0,0.34,4,0.7,0.5,3.7
19,249,935.1,1020,1,25,700,2,1,-1,0.2,84.9,5.8,0,0.05,0.0025,0,0.004,0,0.34,4,0.7,0.5,3.7
20,261,699.05,1025,2,400,1025,2,1,0,0,85.01,5.75,0,0.065,0.002,0.09,0,0,0.305,4.02,0.71,0.505,3.54
21,262,649.55,1025,2,500,1025,2,1,0,0,85.01,5.75,0,0.065,0.002,0.09,0,0,0.305,4.02,0.71,0.505,3.54
22,275,1041.23,1020,1,25,700,2,1.25,-1,0.2,84.9,5.8,0,0.05,0.0025,0,0.004,0,0.34,4,0.7,0.5,3.7
23,285,716,1025,2,375,1025,2,1,0,0,85.01,5.75,0,0.065,0.002,0.09,0,0,0.305,4.02,0.71,0.505,3.54
24,290,1426.014,0,0,350,0,0,0.002,0.1,2,85.09,5.8,0,0.06,0,0,0,0,0.35,4,0.7,0.5,3.5
25,304,1036.68,1020,1,25,700,2,1.25,-1,0.2,84.9,5.8,0,0.05,0.0025,0,0.004,0,0.34,4,0.7,0.5,3.7
26,319,709.07,1025,2,425,1025,2,1,0,0,85.01,5.75,0,0.065,0.002,0.09,0,0,0.305,4.02,0.71,0.505,3.54
27,325,910.82,1020,1,25,0,0,0.8,-1,0.2,84.9,5.8,0,0.05,0.0025,0,0.004,0,0.34,4,0.7,0.5,3.7
28,326,931.73,1020,1,25,700,2,1,-1,0.2,84.9,5.8,0,0.05,0.0025,0,0.004,0,0.34,4,0.7,0.5,3.7
29,334,682.015,1025,2,450,1025,2,1,0,0,85.01,5.75,0,0.065,0.002,0.09,0,0,0.305,4.02,0.71,0.505,3.54
30,336,648.92,1025,2,500,1025,2,1,0,0,85.01,5.75,0,0.065,0.002,0.09,0,0,0.305,4.02,0.71,0.505,3.54
31,370,907.55,1020,1,25,0,0,0.8,-1,0.2,84.9,5.8,0,0.05,0.0025,0,0.004,0,0.34,4,0.7,0.5,3.7
32,370,929.5,1020,1,25,700,2,1,-1,0.2,84.9,5.8,0,0.05,0.0025,0,0.004,0,0.34,4,0.7,0.5,3.7
33,394,706,1025,2,375,1025,2,1,0,0,85.01,5.75,0,0.065,0.002,0.09,0,0,0.305,4.02,0.71,0.505,3.54
34,395,1020.37,1020,1,25,700,2,1.25,-1,0.2,84.9,5.8,0,0.05,0.0025,0,0.004,0,0.34,4,0.7,0.5,3.7
35,395,690.3,1025,2,400,1025,2,1,0,0,85.01,5.75,0,0.065,0.002,0.09,0,0,0.305,4.02,0.71,0.505,3.54
36,399,909.55,1020,1,25,0,0,0.8,-1,0.2,84.9,5.8,0,0.05,0.0025,0,0.004,0,0.34,4,0.7,0.5,3.7
37,401,927.31,1020,1,25,700,2,1,-1,0.2,84.9,5.8,0,0.05,0.0025,0,0.004,0,0.34,4,0.7,0.5,3.7
38,432,679.92,1025,2,450,1025,2,1,0,0,85.01,5.75,0,0.065,0.002,0.09,0,0,0.305,4.02,0.71,0.505,3.54
39,435,644.52,1025,2,500,1025,2,1,0,0,85.01,5.75,0,0.065,0.002,0.09,0,0,0.305,4.02,0.71,0.505,3.54
40,438,708.4,1025,2,425,1025,2,1,0,0,85.01,5.75,0,0.065,0.002,0.09,0,0,0.305,4.02,0.71,0.505,3.54
41,444,900,1020,1,25,0,0,0.8,-1,0.2,84.9,5.8,0,0.05,0.0025,0,0.004,0,0.34,4,0.7,0.5,3.7
42,448,1010.41,1020,1,25,700,2,1.25,-1,0.2,84.9,5.8,0,0.05,0.0025,0,0.004,0,0.34,4,0.7,0.5,3.7
43,461,922.94,1020,1,25,700,2,1,-1,0.2,84.9,5.8,0,0.05,0.0025,0,0.004,0,0.34,4,0.7,0.5,3.7
44,486,1004.95,1020,1,25,700,2,1.25,-1,0.2,84.9,5.8,0,0.05,0.0025,0,0.004,0,0.34,4,0.7,0.5,3.7
45,498,900.87,1020,1,25,0,0,0.8,-1,0.2,84.9,5.8,0,0.05,0.0025,0,0.004,0,0.34,4,0.7,0.5,3.7
46,499,920.73,1020,1,25,700,2,1,-1,0.2,84.9,5.8,0,0.05,0.0025,0,0.004,0,0.34,4,0.7,0.5,3.7
47,516,1000.4,1020,1,25,700,2,1.25,-1,0.2,84.9,5.8,0,0.05,0.0025,0,0.004,0,0.34,4,0.7,0.5,3.7
48,535,694,1025,2,375,1025,2,1,0,0,85.01,5.75,0,0.065,0.002,0.09,0,0,0.305,4.02,0.71,0.505,3.54
49,535,685.86,1025,2,400,1025,2,1,0,0,85.01,5.75,0,0.065,0.002,0.09,0,0,0.305,4.02,0.71,0.505,3.54
50,536,680.69,1025,2,450,1025,2,1,0,0,85.01,5.75,0,0.065,0.002,0.09,0,0,0.305,4.02,0.71,0.505,3.54
51,536,640.4,1025,2,500,1025,2,1,0,0,85.01,5.75,0,0.065,0.002,0.09,0,0,0.305,4.02,0.71,0.505,3.54
52,562,992.248,0,0,25,700,2,1.25,-1,0.2,84.9,5.8,0,0.05,0.0025,0,0.004,0,0.34,4,0.7,0.5,3.7
53,562,1275.41,1020,1,400,0,0,0.002,0.1,2,85.09,5.8,0,0.06,0,0,0,0,0.35,4,0.7,0.5,3.5
54,566,702.24,1025,2,425,1025,2,1,0,0,85.01,5.75,0,0.065,0.002,0.09,0,0,0.305,4.02,0.71,0.505,3.54
55,575,897.49,1020,1,25,0,0,0.8,-1,0.2,84.9,5.8,0,0.05,0.0025,0,0.004,0,0.34,4,0.7,0.5,3.7
56,576,915.26,1020,1,25,700,2,1,-1,0.2,84.9,5.8,0,0.05,0.0025,0,0.004,0,0.34,4,0.7,0.5,3.7
57,594,678.91,1025,2,400,1025,2,1,0,0,85.01,5.75,0,0.065,0.002,0.09,0,0,0.305,4.02,0.71,0.505,3.54
58,596,985.906,1020,1,25,700,2,1.25,-1,0.2,84.9,5.8,0,0.05,0.0025,0,0.004,0,0.34,4,0.7,0.5,3.7
59,607,1193.95,0,0,450,0,0,0.002,0.1,2,85.09,5.8,0,0.06,0,0,0,0,0.35,4,0.7,0.5,3.5
60,612,984.972,1020,1,25,700,2,1.25,-1,0.2,84.9,5.8,0,0.05,0.0025,0,0.004,0,0.34,4,0.7,0.5,3.7
61,621,907.8,1020,1,25,700,2,1,-1,0.2,84.9,5.8,0,0.05,0.0025,0,0.004,0,0.34,4,0.7,0.5,3.7
62,635,678.3,1025,2,450,1025,2,1,0,0,85.01,5.75,0,0.065,0.002,0.09,0,0,0.305,4.02,0.71,0.505,3.54
63,637,682,1025,2,375,1025,2,1,0,0,85.01,5.75,0,0.065,0.002,0.09,0,0,0.305,4.02,0.71,0.505,3.54
64,652,717.14,1025,2,425,1025,2,1,0,0,85.01,5.75,0,0.065,0.002,0.09,0,0,0.305,4.02,0.71,0.505,3.54
65,654,897.25,1020,1,25,0,0,0.8,-1,0.2,84.9,5.8,0,0.05,0.0025,0,0.004,0,0.34,4,0.7,0.5,3.7
66,654,902.47,1020,1,25,700,2,1,-1,0.2,84.9,5.8,0,0.05,0.0025,0,0.004,0,0.34,4,0.7,0.5,3.7
67,654,688.35,1025,2,400,1025,2,1,0,0,85.01,5.75,0,0.065,0.002,0.09,0,0,0.305,4.02,0.71,0.505,3.54
68,668,635.11,1025,2,500,1025,2,1,0,0,85.01,5.75,0,0.065,0.002,0.09,0,0,0.305,4.02,0.71,0.505,3.54
69,677,899.26,1020,1,25,700,2,1,-1,0.2,84.9,5.8,0,0.05,0.0025,0,0.004,0,0.34,4,0.7,0.5,3.7
70,698,892.93,1020,1,25,700,2,1,-1,0.2,84.9,5.8,0,0.05,0.0025,0,0.004,0,0.34,4,0.7,0.5,3.7
71,699,891.88,1020,1,25,0,0,0.8,-1,0.2,84.9,5.8,0,0.05,0.0025,0,0.004,0,0.34,4,0.7,0.5,3.7
72,705,965.078,1020,1,25,700,2,1.25,-1,0.2,84.9,5.8,0,0.05,0.0025,0,0.004,0,0.34,4,0.7,0.5,3.7
73,715,1154.4,0,0,500,0,0,0.002,0.1,2,85.09,5.8,0,0.06,0,0,0,0,0.35,4,0.7,0.5,3.5
74,721,334.21,1020,2,650,1020,2,0.2,0,0,85.09,5.8,0,0.06,0,0,0,0,0.35,4,0.7,0.5,3.5
75,753,883.35,1020,1,25,700,2,1,-1,0.2,84.9,5.8,0,0.05,0.0025,0,0.004,0,0.34,4,0.7,0.5,3.7
76,755,885.43,1020,1,25,0,0,0.8,-1,0.2,84.9,5.8,0,0.05,0.0025,0,0.004,0,0.34,4,0.7,0.5,3.7
77,757,947.974,1020,1,25,700,2,1.25,-1,0.2,84.9,5.8,0,0.05,0.0025,0,0.004,0,0.34,4,0.7,0.5,3.7
78,767,682.22,1025,2,450,1025,2,1,0,0,85.01,5.75,0,0.065,0.002,0.09,0,0,0.305,4.02,0.71,0.505,3.54
79,768,678,1025,2,375,1025,2,1,0,0,85.01,5.75,0,0.065,0.002,0.09,0,0,0.305,4.02,0.71,0.505,3.54
80,778,937.205,1020,1,25,700,2,1.25,-1,0.2,84.9,5.8,0,0.05,0.0025,0,0.004,0,0.34,4,0.7,0.5,3.7
81,800,868.57,1020,1,25,700,2,1,-1,0.2,84.9,5.8,0,0.05,0.0025,0,0.004,0,0.34,4,0.7,0.5,3.7
82,824,689.93,1025,2,400,1025,2,1,0,0,85.01,5.75,0,0.065,0.002,0.09,0,0,0.305,4.02,0.71,0.505,3.54
83,825,726.48,1025,2,425,1025,2,1,0,0,85.01,5.75,0,0.065,0.002,0.09,0,0,0.305,4.02,0.71,0.505,3.54
84,829,886.24,1020,1,25,0,0,0.8,-1,0.2,84.9,5.8,0,0.05,0.0025,0,0.004,0,0.34,4,0.7,0.5,3.7
85,834,848.6,1020,1,25,700,2,1,-1,0.2,84.9,5.8,0,0.05,0.0025,0,0.004,0,0.34,4,0.7,0.5,3.7
86,840,419.78,1020,2,600,1020,2,0.2,0,0,85.09,5.8,0,0.06,0,0,0,0,0.35,4,0.7,0.5,3.5
87,854,1112.62,0,0,600,0,0,0.002,0.1,2,85.09,5.8,0,0.06,0,0,0,0,0.35,4,0.7,0.5,3.5
88,854,688.18,1025,2,450,1025,2,1,0,0,85.01,5.75,0,0.065,0.002,0.09,0,0,0.305,4.02,0.71,0.505,3.54
89,859,638.11,1025,2,500,1025,2,1,0,0,85.01,5.75,0,0.065,0.002,0.09,0,0,0.305,4.02,0.71,0.505,3.54
90,865,680,1025,2,375,1025,2,1,0,0,85.01,5.75,0,0.065,0.002,0.09,0,0,0.305,4.02,0.71,0.505,3.54
91,873,875.65,1020,1,25,0,0,0.8,-1,0.2,84.9,5.8,0,0.05,0.0025,0,0.004,0,0.34,4,0.7,0.5,3.7
92,906,874.51,1020,1,25,0,0,0.8,-1,0.2,84.9,5.8,0,0.05,0.0025,0,0.004,0,0.34,4,0.7,0.5,3.7
93,919,735.035,1025,2,425,1025,2,1,0,0,85.01,5.75,0,0.065,0.002,0.09,0,0,0.305,4.02,0.71,0.505,3.54
94,947,1067.84,0,0,650,0,0,0.002,0.1,2,85.09,5.8,0,0.06,0,0,0,0,0.35,4,0.7,0.5,3.5
95,964,867.01,1020,1,25,0,0,0.8,-1,0.2,84.9,5.8,0,0.05,0.0025,0,0.004,0,0.34,4,0.7,0.5,3.7
96,973,703.91,1025,2,400,1025,2,1,0,0,85.01,5.75,0,0.065,0.002,0.09,0,0,0.305,4.02,0.71,0.505,3.54
97,986,698.72,1025,2,450,1025,2,1,0,0,85.01,5.75,0,0.065,0.002,0.09,0,0,0.305,4.02,0.71,0.505,3.54
98,987,690,1025,2,375,1025,2,1,0,0,85.01,5.75,0,0.065,0.002,0.09,0,0,0.305,4.02,0.71,0.505,3.54
99,1000,494,0,0,550,595,8,0.7,0,0,85.9,6,0,0,0,0,0,0,0.1,2,0,2,4
100,1000,570,0,0,450,595,8,0.7,0,0,85.9,6,0,0,0,0,0,0,0.1,2,0,2,4
101,1000,600,0,0,300,595,8,0.7,0,0,85.9,6,0,0,0,0,0,0,0.1,2,0,2,4
102,1000,494,0,0,25,0,0,0,0,0,89.924,8.96,3.83,0.01,0.009,0.12,0.0016,0.16,0,0,0,0,0
103,1000,570,0,0,25,800,4,0,0,0,89.924,8.96,3.83,0.01,0.009,0.12,0.0016,0.16,0,0,0,0,0
104,1000,600,0,0,25,900,4,0,0,0,89.924,8.96,3.83,0.01,0.009,0.12,0.0016,0.16,0,0,0,0,0
105,1220,444.86,1020,2,500,1020,2,0.2,0,0,85.09,5.8,0,0.06,0,0,0,0,0.35,4,0.7,0.5,3.5
106,1420,637.76,1020,2,400,1020,2,0.2,0,0,85.09,5.8,0,0.06,0,0,0,0,0.35,4,0.7,0.5,3.5
107,1475,561.41,1020,2,450,1020,2,0.2,0,0,85.09,5.8,0,0.06,0,0,0,0,0.35,4,0.7,0.5,3.5
108,1568,673.14,1020,2,350,1020,2,0.2,0,0,85.09,5.8,0,0.06,0,0,0,0,0.35,4,0.7,0.5,3.5
109,10000,400,0,0,550,595,8,0.7,0,0,85.9,6,0,0,0,0,0,0,0.1,2,0,2,4
110,10000,394,0,0,450,595,8,0.7,0,0,85.9,6,0,0,0,0,0,0,0.1,2,0,2,4
111,10000,400,0,0,300,595,8,0.7,0,0,85.9,6,0,0,0,0,0,0,0.1,2,0,2,4
112,10000,400,0,0,25,600,4,0,0,0,89.924,8.96,3.83,0.01,0.009,0.12,0.0016,0.16,0,0,0,0,0
113,10000,394,0,0,25,850,4,0,0,0,89.924,8.96,3.83,0.01,0.009,0.12,0.0016,0.16,0,0,0,0,0
114,27924,500.689,970,0.5,450,700,0.5,2,-1,5,89.34,6.22,4.01,0.02,0.01,0.2,0.001,0.2,0,0,0,0,0
115,43568,459.614,970,0.5,450,700,0.5,2,-1,5,89.34,6.22,4.01,0.02,0.01,0.2,0.001,0.2,0,0,0,0,0
116,52620,430.938,970,0.5,450,700,0.5,2,-1,5,89.34,6.22,4.01,0.02,0.01,0.2,0.001,0.2,0,0,0,0,0
117,59436,400.54,970,0.5,450,700,0.5,2,-1,5,89.34,6.22,4.01,0.02,0.01,0.2,0.001,0.2,0,0,0,0,0
118,61671,369.69,970,0.5,450,700,0.5,2,-1,5,89.34,6.22,4.01,0.02,0.01,0.2,0.001,0.2,0,0,0,0,0
119,99888,340.71,970,0.5,450,700,0.5,2,-1,5,89.34,6.22,4.01,0.02,0.01,0.2,0.001,0.2,0,0,0,0,0
120,100000,675,0,0,25,0,0,0,-1,30,84.69,5.8,0,0.05,0.0025,0.105,0.004,0.009,0.34,4,0.69,0.54,3.72
121,100000,450,932,0,25,704,2,0,-1,60,89.148,6.27,4.19,0,0.012,0.18,0,0.2,0,0,0,0,0
122,100000,667,932,0,25,704,2,0,0.1,60,89.148,6.27,4.19,0,0.012,0.18,0,0.2,0,0,0,0,0
123,100000,860,932,0,25,704,2,0,0.5,60,89.148,6.27,4.19,0,0.012,0.18,0,0.2,0,0,0,0,0
124,100000,950,932,0,25,704,2,0,0.8,60,89.148,6.27,4.19,0,0.012,0.18,0,0.2,0,0,0,0,0
125,100000,700,925,1,25,700,2,0,0.1,50,89.14,6.27,4.19,0,0.012,0.18,0.0041,0.2,0,0,0,0,0
126,100000,850,925,1,25,700,2,0,0.5,50,89.14,6.27,4.19,0,0.012,0.18,0.0041,0.2,0,0,0,0,0
127,100000,710,925,1,25,700,2,0,0.1,50,89.14,6.27,4.19,0,0.012,0.18,0.0041,0.2,0,0,0,0,0
128,100000,681,0,0,25,700,2,0,0.1,90,89.1,6.3,4.2,0,0.013,0.19,0.0041,0.19,0,0,0,0,0
129,100000,725,0,0,25,700,2,0,0,0,89.14,6.27,4.19,0,0.012,0.18,0.0041,0.2,0,0,0,0,0
130,100000,740,0,0,25,500,24,0,0,90,89.14,6.27,4.19,0,0.012,0.18,0.0041,0.2,0,0,0,0,0
131,100000,1100,0,0,25,500,24,0,0,90,89.14,6.27,4.19,0,0.012,0.18,0.0041,0.2,0,0,0,0,0
132,100000,740,0,0,25,500,24,0,0,90,89.14,6.27,4.19,0,0.012,0.18,0.0041,0.2,0,0,0,0,0
133,100000,650,1050,0.25,25,500,24,0,-1,80,89.41,6.4,4,0,0,0.19,0,0,0,0,0,0,0
134,100000,306.28,0,0,25,1300,4,0,0,20,52.39,28.67,0,0.016,0.53,0.002,0.023,0,0,0,18.7,0,0
135,100000,227.24,0,0,400,1300,4,0,0,20,52.39,28.67,0,0.016,0.53,0.002,0.023,0,0,0,18.7,0,0
136,112665,461.077,970,0.5,550,700,0.5,2,-1,5,89.34,6.22,4.01,0.02,0.01,0.2,0.001,0.2,0,0,0,0,0
137,145241,550.017,970,0.5,350,700,0.5,2,-1,5,89.34,6.22,4.01,0.02,0.01,0.2,0.001,0.2,0,0,0,0,0
138,233388,600.83,970,0.5,250,700,0.5,2,-1,5,89.34,6.22,4.01,0.02,0.01,0.2,0.001,0.2,0,0,0,0,0
139,290000,730,0,0,455,600,8,0,0.1,0,85.98,6.2,0,0.021,0.004,0.03,0.008,0,0,1.95,0,2,3.8
140,321569,430.28,970,0.5,550,700,0.5,2,-1,5,89.34,6.22,4.01,0.02,0.01,0.2,0.001,0.2,0,0,0,0,0
141,390678,541.21,970,0.5,350,700,0.5,2,-1,5,89.34,6.22,4.01,0.02,0.01,0.2,0.001,0.2,0,0,0,0,0
142,452387,400.681,970,0.5,550,700,0.5,2,-1,5,89.34,6.22,4.01,0.02,0.01,0.2,0.001,0.2,0,0,0,0,0
143,481796,370.731,970,0.5,550,700,0.5,2,-1,5,89.34,6.22,4.01,0.02,0.01,0.2,0.001,0.2,0,0,0,0,0
144,496004,550.177,970,0.5,250,700,0.5,2,-1,5,89.34,6.22,4.01,0.02,0.01,0.2,0.001,0.2,0,0,0,0,0
145,505165,500.71,970,0.5,350,700,0.5,2,-1,5,89.34,6.22,4.01,0.02,0.01,0.2,0.001,0.2,0,0,0,0,0
146,517945,499.9,970,0.5,250,700,0.5,2,-1,5,89.34,6.22,4.01,0.02,0.01,0.2,0.001,0.2,0,0,0,0,0
147,554811,340.376,970,0.5,550,700,0.5,2,-1,5,89.34,6.22,4.01,0.02,0.01,0.2,0.001,0.2,0,0,0,0,0
148,566076,429.523,970,0.5,250,700,0.5,2,-1,5,89.34,6.22,4.01,0.02,0.01,0.2,0.001,0.2,0,0,0,0,0
149,600000,951,0,0,25,600,8,0,0.1,0,85.98,6.2,0,0.021,0.004,0.03,0.008,0,0,1.95,0,2,3.8
150,600610,429.71,970,0.5,350,700,0.5,2,-1,5,89.34,6.22,4.01,0.02,0.01,0.2,0.001,0.2,0,0,0,0,0
151,682813,369.739,970,0.5,250,700,0.5,2,-1,5,89.34,6.22,4.01,0.02,0.01,0.2,0.001,0.2,0,0,0,0,0
152,718649,369.868,970,0.5,350,700,0.5,2,-1,5,89.34,6.22,4.01,0.02,0.01,0.2,0.001,0.2,0,0,0,0,0
153,998314,339.542,970,0.5,350,700,0.5,2,-1,5,89.34,6.22,4.01,0.02,0.01,0.2,0.001,0.2,0,0,0,0,0
154,1000000,525,0,0,25,0,0,0,-1,30,84.69,5.8,0,0.05,0.0025,0.105,0.004,0.009,0.34,4,0.69,0.54,3.72
155,1000000,300.545,970,0.5,550,700,0.5,2,-1,5,89.34,6.22,4.01,0.02,0.01,0.2,0.001,0.2,0,0,0,0,0
156,1000000,400,932,0,25,704,2,0,-1,60,89.148,6.27,4.19,0,0.012,0.18,0,0.2,0,0,0,0,0
157,1000000,611,932,0,25,704,2,0,0.1,60,89.148,6.27,4.19,0,0.012,0.18,0,0.2,0,0,0,0,0
158,1000000,800,932,0,25,704,2,0,0.5,60,89.148,6.27,4.19,0,0.012,0.18,0,0.2,0,0,0,0,0
159,1000000,920,932,0,25,704,2,0,0.8,60,89.148,6.27,4.19,0,0.012,0.18,0,0.2,0,0,0,0,0
160,1000000,600,925,1,25,700,2,0,0.1,50,89.14,6.27,4.19,0,0.012,0.18,0.0041,0.2,0,0,0,0,0
161,1000000,780,925,1,25,700,2,0,0.5,50,89.14,6.27,4.19,0,0.012,0.18,0.0041,0.2,0,0,0,0,0
162,1000000,610,925,1,25,700,2,0,0.1,50,89.14,6.27,4.19,0,0.012,0.18,0.0041,0.2,0,0,0,0,0
163,1000000,547,0,0,25,700,2,0,0.1,90,89.1,6.3,4.2,0,0.013,0.19,0.0041,0.19,0,0,0,0,0
164,1000000,699,0,0,25,700,2,0,0.5,90,89.1,6.3,4.2,0,0.013,0.19,0.0041,0.19,0,0,0,0,0
165,1000000,700,0,0,25,700,2,0,0,0,89.14,6.27,4.19,0,0.012,0.18,0.0041,0.2,0,0,0,0,0
166,1000000,730,0,0,25,500,24,0,0,90,89.14,6.27,4.19,0,0.012,0.18,0.0041,0.2,0,0,0,0,0
167,1000000,875,0,0,25,500,24,0,0,90,89.14,6.27,4.19,0,0.012,0.18,0.0041,0.2,0,0,0,0,0
168,1000000,690,0,0,25,500,24,0,0,90,89.14,6.27,4.19,0,0.012,0.18,0.0041,0.2,0,0,0,0,0
169,1000000,630,1050,0.25,25,500,24,0,-1,80,89.41,6.4,4,0,0,0.19,0,0,0,0,0,0,0
170,1000000,282.17,0,0,25,1300,4,0,0,20,52.39,28.67,0,0.016,0.53,0.002,0.023,0,0,0,18.7,0,0
171,1000000,218.83,0,0,400,1300,4,0,0,20,52.39,28.67,0,0.016,0.53,0.002,0.023,0,0,0,18.7,0,0
172,1000000,312.44,0,0,600,1300,4,0,0,20,52.39,28.67,0,0.016,0.53,0.002,0.023,0,0,0,18.7,0,0
173,1000000,295.63,0,0,750,1300,4,0,0,20,52.39,28.67,0,0.016,0.53,0.002,0.023,0,0,0,18.7,0,0
174,1001439,340.73,970,0.5,250,700,0.5,2,-1,5,89.34,6.22,4.01,0.02,0.01,0.2,0.001,0.2,0,0,0,0,0
175,1834944,901.85,970,0.5,25,700,0.5,2,-1,5,89.34,6.22,4.01,0.02,0.01,0.2,0.001,0.2,0,0,0,0,0
176,2600000,703,0,0,455,600,8,0,0.1,0,85.98,6.2,0,0.021,0.004,0.03,0.008,0,0,1.95,0,2,3.8
177,2683559,853.92,970,0.5,25,700,0.5,2,-1,5,89.34,6.22,4.01,0.02,0.01,0.2,0.001,0.2,0,0,0,0,0
178,3589513,672.47,970,0.5,25,700,0.5,2,-1,5,89.34,6.22,4.01,0.02,0.01,0.2,0.001,0.2,0,0,0,0,0
179,4185837,556.063,970,0.5,25,700,0.5,2,-1,5,89.34,6.22,4.01,0.02,0.01,0.2,0.001,0.2,0,0,0,0,0
180,4740000,540,0,0,25,0,0,0,-1,20000,89.31,6.29,4.11,0.08,0.03,0.13,0,0.05,0,0,0,0,0
181,4805097,464.76,970,0.5,25,700,0.5,2,-1,5,89.34,6.22,4.01,0.02,0.01,0.2,0.001,0.2,0,0,0,0,0
182,5344083,404.28,970,0.5,25,700,0.5,2,-1,5,89.34,6.22,4.01,0.02,0.01,0.2,0.001,0.2,0,0,0,0,0
183,6000000,621,0,0,455,600,8,0,0.1,0,85.98,6.2,0,0.021,0.004,0.03,0.008,0,0,1.95,0,2,3.8
184,10000000,500,0,0,25,0,0,0,-1,30,84.69,5.8,0,0.05,0.0025,0.105,0.004,0.009,0.34,4,0.69,0.54,3.72
185,10000000,460,0,0,600,0,0,0,0.1,30,84.69,5.8,0,0.05,0.0025,0.105,0.004,0.009,0.34,4,0.69,0.54,3.72
186,10000000,373.467,970,0.5,25,700,0.5,2,-1,5,89.34,6.22,4.01,0.02,0.01,0.2,0.001,0.2,0,0,0,0,0
187,10000000,390,932,0,25,704,2,0,-1,60,89.148,6.27,4.19,0,0.012,0.18,0,0.2,0,0,0,0,0
188,10000000,556,932,0,25,704,2,0,0.1,60,89.148,6.27,4.19,0,0.012,0.18,0,0.2,0,0,0,0,0
189,10000000,640,932,0,25,704,2,0,0.5,60,89.148,6.27,4.19,0,0.012,0.18,0,0.2,0,0,0,0,0
190,10000000,900,932,0,25,704,2,0,0.8,60,89.148,6.27,4.19,0,0.012,0.18,0,0.2,0,0,0,0,0
191,10000000,540,925,1,25,700,2,0,0.1,50,89.14,6.27,4.19,0,0.012,0.18,0.0041,0.2,0,0,0,0,0
192,10000000,640,925,1,25,700,2,0,0.5,50,89.14,6.27,4.19,0,0.012,0.18,0.0041,0.2,0,0,0,0,0
193,10000000,520,0,0,25,0,0,0,-1,20000,89.31,6.29,4.11,0.08,0.03,0.13,0,0.05,0,0,0,0,0
194,10000000,498,0,0,25,700,2,0,0.1,90,89.1,6.3,4.2,0,0.013,0.19,0.0041,0.19,0,0,0,0,0
195,10000000,582,0,0,25,700,2,0,0.5,90,89.1,6.3,4.2,0,0.013,0.19,0.0041,0.19,0,0,0,0,0
196,10000000,680,0,0,25,700,2,0,0,0,89.14,6.27,4.19,0,0.012,0.18,0.0041,0.2,0,0,0,0,0
197,10000000,540,0,0,25,500,24,0,0,90,89.14,6.27,4.19,0,0.012,0.18,0.0041,0.2,0,0,0,0,0
198,10000000,600,0,0,25,500,24,0,0,90,89.14,6.27,4.19,0,0.012,0.18,0.0041,0.2,0,0,0,0,0
199,10000000,730,0,0,25,500,24,0,0,90,89.14,6.27,4.19,0,0.012,0.18,0.0041,0.2,0,0,0,0,0
200,10000000,800,0,0,25,500,24,0,0,90,89.14,6.27,4.19,0,0.012,0.18,0.0041,0.2,0,0,0,0,0
201,10000000,680,0,0,25,500,24,0,0,90,89.14,6.27,4.19,0,0.012,0.18,0.0041,0.2,0,0,0,0,0
202,10000000,620,1050,0.25,25,500,24,0,-1,80,89.41,6.4,4,0,0,0.19,0,0,0,0,0,0,0
203,10000000,750,0,0,25,595,8,0,0.1,100,82,6,0,0,0,0,0,0,0,2,0,6,4
204,10000000,268.16,0,0,25,1300,4,0,0,20,52.39,28.67,0,0.016,0.53,0.002,0.023,0,0,0,18.7,0,0
205,10000000,206.5,0,0,400,1300,4,0,0,20,52.39,28.67,0,0.016,0.53,0.002,0.023,0,0,0,18.7,0,0
206,10000000,298.43,0,0,600,1300,4,0,0,20,52.39,28.67,0,0.016,0.53,0.002,0.023,0,0,0,18.7,0,0
207,12572495,1098.35,0,0,25,800,2,0,0.1,6,84.83,6.12,0,0.01,0.01,0.1,0.009,0.1,0.1,2.18,0,2.19,4.35
208,22483487,1045.65,0,0,25,800,2,0,0.1,6,84.83,6.12,0,0.01,0.01,0.1,0.009,0.1,0.1,2.18,0,2.19,4.35
209,30000000,703,0,0,25,600,8,0,0.1,0,85.98,6.2,0,0.021,0.004,0.03,0.008,0,0,1.95,0,2,3.8
210,34482918,947.76,0,0,25,800,2,0,0.1,6,84.83,6.12,0,0.01,0.01,0.1,0.009,0.1,0.1,2.18,0,2.19,4.35
211,39420453,846.12,0,0,25,800,2,0,0.1,6,84.83,6.12,0,0.01,0.01,0.1,0.009,0.1,0.1,2.18,0,2.19,4.35
212,47590556,695.53,0,0,25,800,2,0,0.1,6,84.83,6.12,0,0.01,0.01,0.1,0.009,0.1,0.1,2.18,0,2.19,4.35
213,55964069,597.65,0,0,25,800,2,0,0.1,6,84.83,6.12,0,0.01,0.01,0.1,0.009,0.1,0.1,2.18,0,2.19,4.35
214,75226561,546.882,0,0,25,800,2,0,0.1,6,84.83,6.12,0,0.01,0.01,0.1,0.009,0.1,0.1,2.18,0,2.19,4.35
215,94680341,497.88,0,0,25,800,2,0,0.1,6,84.83,6.12,0,0.01,0.01,0.1,0.009,0.1,0.1,2.18,0,2.19,4.35
216,100000000,500,0,0,25,0,0,0,-1,30,84.69,5.8,0,0.05,0.0025,0.105,0.004,0.009,0.34,4,0.69,0.54,3.72
217,100000000,400,0,0,600,0,0,0,0.1,30,84.69,5.8,0,0.05,0.0025,0.105,0.004,0.009,0.34,4,0.69,0.54,3.72
218,100000000,253.59,0,0,25,1300,4,0,0,20,52.39,28.67,0,0.016,0.53,0.002,0.023,0,0,0,18.7,0,0
219,100000000,180.72,0,0,400,1300,4,0,0,20,52.39,28.67,0,0.016,0.53,0.002,0.023,0,0,0,18.7,0,0
220,100000000,282.17,0,0,600,1300,4,0,0,20,52.39,28.67,0,0.016,0.53,0.002,0.023,0,0,0,18.7,0,0
221,100000000,293.94,0,0,750,1300,4,0,0,20,52.39,28.67,0,0.016,0.53,0.002,0.023,0,0,0,18.7,0,0
222,185000000,500,0,0,25,0,0,0,-1,20000,89.31,6.29,4.11,0.08,0.03,0.13,0,0.05,0,0,0,0,0